<?xml version="1.0"?>
<robot name="jedi_robot">
  
  <!-- 材质定义 -->
  <material name="brown">
    <color rgba="0.6 0.4 0.2 1.0"/>
  </material>
  <material name="beige">
    <color rgba="0.96 0.96 0.86 1.0"/>
  </material>
  <material name="lightsaber_blue">
    <color rgba="0.0 0.0 1.0 0.8"/>
  </material>
  <material name="black">
    <color rgba="0.0 0.0 0.0 1.0"/>
  </material>
  <material name="silver">
    <color rgba="0.75 0.75 0.75 1.0"/>
  </material>

  <!-- 躯干（基础连接点） -->
  <link name="base_link">
    <visual>
      <geometry>
        <box size="0.4 0.3 0.6"/>
      </geometry>
      <material name="brown"/>
      <origin xyz="0 0 0" rpy="0 0 0"/>
    </visual>
    <collision>
      <geometry>
        <box size="0.4 0.3 0.6"/>
      </geometry>
    </collision>
    <inertial>
      <mass value="5.0"/>
      <inertia ixx="0.1" ixy="0.0" ixz="0.0" iyy="0.1" iyz="0.0" izz="0.1"/>
    </inertial>
  </link>

  <!-- 头部 -->
  <joint name="head_joint" type="revolute">
    <parent link="base_link"/>
    <child link="head"/>
    <origin xyz="0 0 0.35" rpy="0 0 0"/>
    <axis xyz="0 0 1"/>
    <limit lower="-1.0" upper="1.0" effort="10" velocity="1.0"/>
  </joint>
  
  <link name="head">
    <visual>
      <geometry>
        <sphere radius="0.15"/>
      </geometry>
      <material name="beige"/>
    </visual>
    <collision>
      <geometry>
        <sphere radius="0.15"/>
      </geometry>
    </collision>
    <inertial>
      <mass value="1.0"/>
      <inertia ixx="0.01" ixy="0.0" ixz="0.0" iyy="0.01" iyz="0.0" izz="0.01"/>
    </inertial>
  </link>
  
  <!-- 头巾/兜帽 -->
  <joint name="hood_joint" type="fixed">
    <parent link="head"/>
    <child link="hood"/>
    <origin xyz="0 0 0.05" rpy="0 0 0"/>
  </joint>
  
  <link name="hood">
    <visual>
      <geometry>
        <box size="0.2 0.25 0.1"/>
      </geometry>
      <material name="brown"/>
      <origin xyz="0 0 0.05" rpy="0 0 0"/>
    </visual>
  </link>

  <!-- 右臂 -->
  <!-- 肩部 -->
  <joint name="right_shoulder" type="revolute">
    <parent link="base_link"/>
    <child link="right_upper_arm"/>
    <origin xyz="0.2 0 0.2" rpy="0 0 0"/>
    <axis xyz="0 1 0"/>
    <limit lower="-1.5" upper="1.5" effort="10" velocity="1.0"/>
  </joint>
  
  <link name="right_upper_arm">
    <visual>
      <geometry>
        <cylinder length="0.3" radius="0.05"/>
      </geometry>
      <material name="brown"/>
      <origin xyz="0 0 -0.15" rpy="0 0 0"/>
    </visual>
    <collision>
      <geometry>
        <cylinder length="0.3" radius="0.05"/>
      </geometry>
      <origin xyz="0 0 -0.15" rpy="0 0 0"/>
    </collision>
    <inertial>
      <mass value="1.0"/>
      <inertia ixx="0.01" ixy="0.0" ixz="0.0" iyy="0.01" iyz="0.0" izz="0.01"/>
    </inertial>
  </link>
  
  <!-- 肘部 -->
  <joint name="right_elbow" type="revolute">
    <parent link="right_upper_arm"/>
    <child link="right_lower_arm"/>
    <origin xyz="0 0 -0.3" rpy="0 0 0"/>
    <axis xyz="0 1 0"/>
    <limit lower="0" upper="2.5" effort="10" velocity="1.0"/>
  </joint>
  
  <link name="right_lower_arm">
    <visual>
      <geometry>
        <cylinder length="0.3" radius="0.04"/>
      </geometry>
      <material name="brown"/>
      <origin xyz="0 0 -0.15" rpy="0 0 0"/>
    </visual>
    <collision>
      <geometry>
        <cylinder length="0.3" radius="0.04"/>
      </geometry>
      <origin xyz="0 0 -0.15" rpy="0 0 0"/>
    </collision>
    <inertial>
      <mass value="0.8"/>
      <inertia ixx="0.008" ixy="0.0" ixz="0.0" iyy="0.008" iyz="0.0" izz="0.008"/>
    </inertial>
  </link>
  
  <!-- 手部 -->
  <joint name="right_hand_joint" type="fixed">
    <parent link="right_lower_arm"/>
    <child link="right_hand"/>
    <origin xyz="0 0 -0.3" rpy="0 0 0"/>
  </joint>
  
  <link name="right_hand">
    <visual>
      <geometry>
        <sphere radius="0.05"/>
      </geometry>
      <material name="beige"/>
    </visual>
    <collision>
      <geometry>
        <sphere radius="0.05"/>
      </geometry>
    </collision>
    <inertial>
      <mass value="0.2"/>
      <inertia ixx="0.001" ixy="0.0" ixz="0.0" iyy="0.001" iyz="0.0" izz="0.001"/>
    </inertial>
  </link>
  
  <!-- 光剑 -->
  <joint name="lightsaber_joint" type="fixed">
    <parent link="right_hand"/>
    <child link="lightsaber_hilt"/>
    <origin xyz="0.05 0 0" rpy="0 0 0"/>
  </joint>
  
  <link name="lightsaber_hilt">
    <visual>
      <geometry>
        <cylinder length="0.15" radius="0.02"/>
      </geometry>
      <material name="silver"/>
      <origin xyz="0 0 -0.075" rpy="0 0 0"/>
    </visual>
    <collision>
      <geometry>
        <cylinder length="0.15" radius="0.02"/>
      </geometry>
      <origin xyz="0 0 -0.075" rpy="0 0 0"/>
    </collision>
    <inertial>
      <mass value="0.3"/>
           <inertia ixx="0.001" ixy="0.0" ixz="0.0" iyy="0.001" iyz="0.0" izz="0.001"/>
    </inertial>
  </link>
  
  <!-- 光剑剑刃 -->
  <joint name="lightsaber_blade_joint" type="fixed">
    <parent link="lightsaber_hilt"/>
    <child link="lightsaber_blade"/>
    <origin xyz="0 0 -0.15" rpy="0 0 0"/>
  </joint>
  
  <link name="lightsaber_blade">
    <visual>
      <geometry>
        <cylinder length="0.8" radius="0.015"/>
      </geometry>
      <material name="lightsaber_blue"/>
      <origin xyz="0 0 -0.4" rpy="0 0 0"/>
    </visual>
  </link>
  
  <!-- 左臂 -->
  <!-- 肩部 -->
  <joint name="left_shoulder" type="revolute">
    <parent link="base_link"/>
    <child link="left_upper_arm"/>
    <origin xyz="-0.2 0 0.2" rpy="0 0 0"/>
    <axis xyz="0 1 0"/>
    <limit lower="-1.5" upper="1.5" effort="10" velocity="1.0"/>
  </joint>
  
  <link name="left_upper_arm">
    <visual>
      <geometry>
        <cylinder length="0.3" radius="0.05"/>
      </geometry>
      <material name="brown"/>
      <origin xyz="0 0 -0.15" rpy="0 0 0"/>
    </visual>
    <collision>
      <geometry>
        <cylinder length="0.3" radius="0.05"/>
      </geometry>
      <origin xyz="0 0 -0.15" rpy="0 0 0"/>
    </collision>
    <inertial>
      <mass value="1.0"/>
      <inertia ixx="0.01" ixy="0.0" ixz="0.0" iyy="0.01" iyz="0.0" izz="0.01"/>
    </inertial>
  </link>
  
  <!-- 肘部 -->
  <joint name="left_elbow" type="revolute">
    <parent link="left_upper_arm"/>
    <child link="left_lower_arm"/>
    <origin xyz="0 0 -0.3" rpy="0 0 0"/>
    <axis xyz="0 1 0"/>
    <limit lower="0" upper="2.5" effort="10" velocity="1.0"/>
  </joint>
  
  <link name="left_lower_arm">
    <visual>
      <geometry>
        <cylinder length="0.3" radius="0.04"/>
      </geometry>
      <material name="brown"/>
      <origin xyz="0 0 -0.15" rpy="0 0 0"/>
    </visual>
    <collision>
      <geometry>
        <cylinder length="0.3" radius="0.04"/>
      </geometry>
      <origin xyz="0 0 -0.15" rpy="0 0 0"/>
    </collision>
    <inertial>
      <mass value="0.8"/>
      <inertia ixx="0.008" ixy="0.0" ixz="0.0" iyy="0.008" iyz="0.0" izz="0.008"/>
    </inertial>
  </link>
  
  <!-- 手部 -->
  <joint name="left_hand_joint" type="fixed">
    <parent link="left_lower_arm"/>
    <child link="left_hand"/>
    <origin xyz="0 0 -0.3" rpy="0 0 0"/>
  </joint>
  
  <link name="left_hand">
    <visual>
      <geometry>
        <sphere radius="0.05"/>
      </geometry>
      <material name="beige"/>
    </visual>
    <collision>
      <geometry>
        <sphere radius="0.05"/>
      </geometry>
    </collision>
    <inertial>
      <mass value="0.2"/>
      <inertia ixx="0.001" ixy="0.0" ixz="0.0" iyy="0.001" iyz="0.0" izz="0.001"/>
    </inertial>
  </link>
  
  <!-- 右腿 -->
  <joint name="right_hip" type="revolute">
    <parent link="base_link"/>
    <child link="right_upper_leg"/>
    <origin xyz="0.1 0 -0.3" rpy="0 0 0"/>
    <axis xyz="0 1 0"/>
    <limit lower="-1.0" upper="1.0" effort="10" velocity="1.0"/>
  </joint>
  
  <link name="right_upper_leg">
    <visual>
      <geometry>
        <cylinder length="0.4" radius="0.06"/>
      </geometry>
      <material name="brown"/>
      <origin xyz="0 0 -0.2" rpy="0 0 0"/>
    </visual>
    <collision>
      <geometry>
        <cylinder length="0.4" radius="0.06"/>
      </geometry>
      <origin xyz="0 0 -0.2" rpy="0 0 0"/>
    </collision>
    <inertial>
      <mass value="1.5"/>
      <inertia ixx="0.02" ixy="0.0" ixz="0.0" iyy="0.02" iyz="0.0" izz="0.02"/>
    </inertial>
  </link>
  
  <!-- 膝盖 -->
  <joint name="right_knee" type="revolute">
    <parent link="right_upper_leg"/>
    <child link="right_lower_leg"/>
    <origin xyz="0 0 -0.4" rpy="0 0 0"/>
    <axis xyz="0 1 0"/>
    <limit lower="0" upper="2.5" effort="10" velocity="1.0"/>
  </joint>
  
  <link name="right_lower_leg">
    <visual>
      <geometry>
        <cylinder length="0.4" radius="0.05"/>
      </geometry>
      <material name="brown"/>
      <origin xyz="0 0 -0.2" rpy="0 0 0"/>
    </visual>
    <collision>
      <geometry>
        <cylinder length="0.4" radius="0.05"/>
      </geometry>
      <origin xyz="0 0 -0.2" rpy="0 0 0"/>
    </collision>
    <inertial>
      <mass value="1.0"/>
      <inertia ixx="0.01" ixy="0.0" ixz="0.0" iyy="0.01" iyz="0.0" izz="0.01"/>
    </inertial>
  </link>
  
  <!-- 右脚 -->
  <joint name="right_ankle" type="fixed">
    <parent link="right_lower_leg"/>
    <child link="right_foot"/>
    <origin xyz="0 0 -0.4" rpy="0 0 0"/>
  </joint>
  
  <link name="right_foot">
    <visual>
      <geometry>
        <box size="0.1 0.2 0.05"/>
      </geometry>
      <material name="black"/>
      <origin xyz="0.05 0 0" rpy="0 0 0"/>
    </visual>
    <collision>
      <geometry>
        <box size="0.1 0.2 0.05"/>
      </geometry>
      <origin xyz="0.05 0 0" rpy="0 0 0"/>
    </collision>
    <inertial>
      <mass value="0.5"/>
      <inertia ixx="0.001" ixy="0.0" ixz="0.0" iyy="0.001" iyz="0.0" izz="0.001"/>
    </inertial>
  </link>
  
  <!-- 左腿 -->
  <joint name="left_hip" type="revolute">
    <parent link="base_link"/>
    <child link="left_upper_leg"/>
    <origin xyz="-0.1 0 -0.3" rpy="0 0 0"/>
    <axis xyz="0 1 0"/>
    <limit lower="-1.0" upper="1.0" effort="10" velocity="1.0"/>
  </joint>
  
  <link name="left_upper_leg">
    <visual>
      <geometry>
        <cylinder length="0.4" radius="0.06"/>
      </geometry>
      <material name="brown"/>
      <origin xyz="0 0 -0.2" rpy="0 0 0"/>
    </visual>
    <collision>
      <geometry>
        <cylinder length="0.4" radius="0.06"/>
      </geometry>
      <origin xyz="0 0 -0.2" rpy="0 0 0"/>
    </collision>
    <inertial>
      <mass value="1.5"/>
      <inertia ixx="0.02" ixy="0.0" ixz="0.0" iyy="0.02" iyz="0.0" izz="0.02"/>
    </inertial>
  </link>
  
  <!-- 膝盖 -->
  <joint name="left_knee" type="revolute">
    <parent link="left_upper_leg"/>
    <child link="left_lower_leg"/>
    <origin xyz="0 0 -0.4" rpy="0 0 0"/>
    <axis xyz="0 1 0"/>
    <limit lower="0" upper="2.5" effort="10" velocity="1.0"/>
  </joint>
  
  <link name="left_lower_leg">
    <visual>
      <geometry>
        <cylinder length="0.4" radius="0.05"/>
      </geometry>
      <material name="brown"/>
      <origin xyz="0 0 -0.2" rpy="0 0 0"/>
    </visual>
    <collision>
      <geometry>
        <cylinder length="0.4" radius="0.05"/>
      </geometry>
      <origin xyz="0 0 -0.2" rpy="0 0 0"/>
    </collision>
    <inertial>
      <mass value="1.0"/>
      <inertia ixx="0.01" ixy="0.0" ixz="0.0" iyy="0.01" iyz="0.0" izz="0.01"/>
    </inertial>
  </link>
  
  <!-- 左脚 -->
  <joint name="left_ankle" type="fixed">
    <parent link="left_lower_leg"/>
    <child link="left_foot"/>
    <origin xyz="0 0 -0.4" rpy="0 0 0"/>
  </joint>
  
  <link name="left_foot">
    <visual>
      <geometry>
        <box size="0.1 0.2 0.05"/>
      </geometry>
      <material name="black"/>
      <origin xyz="0.05 0 0" rpy="0 0 0"/>
    </visual>
    <collision>
      <geometry>
        <box size="0.1 0.2 0.05"/>
      </geometry>
      <origin xyz="0.05 0 0" rpy="0 0 0"/>
    </collision>
    <inertial>
      <mass value="0.5"/>
      <inertia ixx="0.001" ixy="0.0" ixz="0.0" iyy="0.001" iyz="0.0" izz="0.001"/>
    </inertial>
  </link>
  
  <!-- 绝地长袍 - 前后两片 -->
  <joint name="robe_front_joint" type="fixed">
    <parent link="base_link"/>
    <child link="robe_front"/>
    <origin xyz="0 0.15 -0.1" rpy="0 0 0"/>
  </joint>
  
  <link name="robe_front">
    <visual>
      <geometry>
        <box size="0.35 0.02 0.8"/>
      </geometry>
      <material name="brown"/>
      <origin xyz="0 0 -0.4" rpy="0 0 0"/>
    </visual>
  </link>
  
  <joint name="robe_back_joint" type="fixed">
    <parent link="base_link"/>
    <child link="robe_back"/>
    <origin xyz="0 -0.15 -0.1" rpy="0 0 0"/>
  </joint>
  
  <link name="robe_back">
    <visual>
      <geometry>
        <box size="0.35 0.02 0.9"/>
      </geometry>
      <material name="brown"/>
      <origin xyz="0 0 -0.45" rpy="0 0 0"/>
    </visual>
  </link>
  
</robot>
